Workbook
Name ASCENCEURS: FORMULES!$AN$2:$AN$6
Name CARRELAGE_FAIENCE: FORMULES!$AB$2:$AB$7
Name cb_ChuteHauteur: 'FICHE DE PREVENTION'!$B$26
Name cb_Echafaudages: 'FICHE DE PREVENTION'!$D$31
Name cb_GardeCorps: 'FICHE DE PREVENTION'!$D$30
Name cb_Harnais: 'FICHE DE PREVENTION'!$B$36
Name cb_ProcHauteur: 'FICHE DE PREVENTION'!$F$33
Name CHARGE_OPERATION: FORMULES!$A$35:$A$61
Name CHARPENTE: FORMULES!$J$2:$J$13
Name CHAUFFAGE: FORMULES!$AJ$2:$AJ$6
Name COUVERTURE: FORMULES!$L$2:$L$14
Name DEMOLITION: FORMULES!$F$2:$F$18
Name DESAMIANTAGE: FORMULES!$D$2:$D$8
Name DOUBLAGE_FAUX_PLAFOND_CLOISONS: FORMULES!$R$2:$R$7
Name ELECTRICITE: FORMULES!$AL$2:$AL$9
Name ESPACES_VERTS: FORMULES!$AP$2:$AP$15
Name ETANCHEITE: FORMULES!$N$2:$N$11
Name GROS_OEUVRE: FORMULES!$H$2:$H$22
Name ISOLATION: FORMULES!$T$2:$T$10
Name LOT: FORMULES!$B$2:$B$23
Name MENUISERIES_EXTERIEURES: FORMULES!$X$2:$X$5
Name MENUISERIES_INTERIEURES: FORMULES!$V$2:$V$5
Name PEINTURE_REVETEMENTS_DE_SOL: FORMULES!$AD$2:$AD$11
Name PLOMBERIE: FORMULES!$AF$2:$AF$11
Name RAVALEMENT_ENDUIT: FORMULES!$P$2:$P$11
Name SERRURERIE: FORMULES!$Z$2:$Z$8
Name TOUT_CORPS_ETAT: FORMULES!#REF!
Name VENTILATION: FORMULES!$AH$2:$AH$6
Name VOIRIES_RESEAUX_DIVERS: FORMULES!$AR$2:$AR$29

Sheet FICHE DE PREVENTION
F2: PLAN DE PREVENTION
A4: LOT TRAVAUX | C4: SERRURERIE
A5: Libellé de la tâche | C5: Poser une main courante en extérieur
A6: Période d’intervention | C6: du 18/09/2026 au 16/10/2026
A7: Numéro de bon de commande : | C7: 5117817
A9: Nature de l’activité : | E9: Procédure en cas d’accident / incident :
A10: Remplacement d'une carte électronique de commande caisson VMC | E10: Personne à alerter :
E11: HATIM ALLEL
E12: =VLOOKUP(E11,FORMULES!A35:F109,3,FALSE) -> 06 43 25 48 05
E13: =VLOOKUP(E11,FORMULES!A35:F109,5,FALSE) -> hatim.allel@plurial.fr
A14: Zone concernée : | E14: OU
A15: RUE DE LIERS, AVENUE SAINT SAENS ET RUE BIZET, SMSO | E15: CENTRE DE RELATION CLIENTS
E16: 03 26 04 98 11
A18: Moyens techniques utilisés : | E18: Procédure d’alerte (numéro d'alertes) :
E19: 15 | F19: SAMU
E20: 18 | F20: POMPIERS
E21: 114 | F21: URGENCES
E22: 17 | F22: POLICE SECOURS
A23: Risques identifiés :
A24: FALSE | B24: Amiante/plomb | C24: FALSE | D24: Coupure/sectionnement | E24: FALSE | F24: Vibration
A25: FALSE | B25: Bruit | C25: FALSE | D25: Heurt | E25: TRUE | F25: Risque électrique
A26: TRUE | B26: Chute de hauteur | C26: FALSE | D26: Incendie/explosion | E26: FALSE | F26: Risque routier
A27: TRUE | B27: Chute de plain-pied | C27: FALSE | D27: Troubles musculosquelettiques | E27: FALSE | F27: Forte chaleur
A28: TRUE | B28: Chute d’objet | C28: FALSE | D28: Produit chimique
A29: Mesures de prévention mises en place :
A30: =OR(A28,C25) -> TRUE | B30: Casque de sécurité | C30: =$A$26 -> TRUE | D30: Garde corps / filet antichute | E30: =$E$25 -> TRUE | F30: Mise à la terre des équipements
A31: =OR($A$24:$A$28,$C$24:$C$28,$E$24:$E$27) -> TRUE | B31: Chaussure de sécurité | C31: =$A$26 -> TRUE | D31: Echafaudages | E31: =E26 -> FALSE | F31: Formation et autorisation pour engins
A32: =OR(C24,C28) -> FALSE | B32: Gants | C32: =A28 -> TRUE | D32: Protection des trémies et ouvertures | E32: =$E$25 -> TRUE | F32: Matériel électrique conforme et vérifié
A33: =OR(C25,E26) -> FALSE | B33: Vêtements haute visibilité | C33: FALSE | D33: Eclairage suffisant du chantier | E33: =$A$26 -> TRUE | F33: Procédure de travail en hauteur sécurisée
A34: =A25 -> FALSE | B34: Protection auditive | C34: =OR($A$24:$A$28,$C$24:$C$28,$E$24:$E$27) -> TRUE | D34: Rangement et nettoyage régulier | E34: =C26 -> FALSE | F34: Permis feu si travail par flamme (soudure, meulage)
A35: =C24 -> FALSE | B35: Lunettes / visière de protection | C35: =C28 -> FALSE | D35: Stockage sécurisé des matériaux / produit dangereux | E35: =A24 -> FALSE | F35: Plan de prévention amiantes / plomb
A36: =$A$26 -> TRUE | B36: Harnais antichute | C36: =C26 -> FALSE | D36: Extincteurs disponibles et vérifiés | E36: =OR($A$24:$A$28,$C$24:$C$28,$E$24:$E$27) -> TRUE | F36: Trousse de premiers secours sur place
A37: =OR(A24,C28) -> FALSE | B37: Masque | C37: =$E$25 -> TRUE | D37: Protection des câbles | E37: FALSE | F37: Personnel formés aux gestes de premiers secours
A38: =OR(A24,C24) -> FALSE | B38: Tenue de protection | C38: =OR(C27,E24) -> FALSE | D38: Temps de pause lors de tâches pénibles | E38: =E27 -> FALSE | F38: Pauses fraicheurs (hydratation)
A40: VALIDATION DE LA FICHE
A41: Rédacteur de la fiche : | C41: =E11 -> HATIM ALLEL
A42: Numéro de téléphone : | C42: =E12 -> 06 43 25 48 05
A43: Adresse mail : | C43: =E13 -> hatim.allel@plurial.fr
A44: Date de rédaction : | C44: 46283
A45: SIGNATURE DE L'ENTREPRISE :

Sheet FORMULES
B1: LOT | D1: DESAMIANTAGE | F1: DEMOLITION | H1: GROS_ŒUVRE | J1: CHARPENTE | L1: COUVERTURE | N1: ETANCHEITE | P1: RAVALEMENT_ENDUIT | R1: DOUBLAGE_FAUX_PLAFOND_CLOISONS | T1: ISOLATION | V1: MENUISERIES_INTERIEURES | X1: MENUISERIES_EXTERIEURES | Z1: SERRURERIE | AB1: CARRELAGE_FAIENCE | AD1: PEINTURE_REVETEMENTS_DE_SOL | AF1: PLOMBERIE | AH1: VENTILATION | AJ1: CHAUFFAGE | AL1: ELECTRICITE | AN1: ASCENCEURS | AP1: ESPACES_VERTS | AR1: VOIRIES_RESEAUX_DIVERS
B2: DESAMIANTAGE | D2: ='LOT 1'!B5 -> Dépose de plaques ou éléments en amiante-ciment (toiture, conduits, bardage) | F2: ='LOT 2'!B4 -> Dépose des éléments non porteurs : cloisons, plafonds, doublages | H2: ='LOT 3'!B4 -> Réalisation de semelles filantes ou isolées en béton armé | J2: ='LOT 4'!B4 -> Dépose de l’ancienne charpente ou de parties défectueuses | L2: ='LOT 5'!B4 -> Dépose des éléments de couverture (tuiles, ardoises, bac acier) | N2: ='LOT 6'!B4 -> Pose de membranes bitumineuses (torchis, rouleaux) | P2: ='LOT 7'!B4 -> Nettoyage des façades (haute pression, sablage, gommage, peeling selon nature du support) | R2: ='LOT 8'!B4 -> Mise en place de l’isolation thermique, acoustique ou pare-vapeur dans les doublages ou cloisons | T2: ='LOT 9'!B4 -> POSE ITE : Pose d'isolant par collage ou fixation mécanique (chevilles à rosace) | V2: ='LOT 10'!B3 -> Pose des habillages divers (plinthes compris) | X2: ='LOT 11'!B3 -> Pose d'une portée d'entrée de bâtiment | Z2: ='LOT 12'!B3 -> Pose d'une portée d'entrée de bâtiment | AB2: ='LOT 13'!B4 -> Application d’un primaire d’accrochage si nécessaire | AD2: ='LOT 14'!B4 -> Application des couches de peinture (primaire, finition) | AF2: ='LOT 15'!B3 -> Poser un réseau multicouche | AH2: ='LOT 16'!B3 -> Poser des gaines de ventilation | AJ2: ='LOT 17'!B3 -> Poser une chaudière gaz | AL2: ='LOT 18'!B3 -> Installer le réseau téléphonique | AN2: ='LOT 19'!B5 -> Installation d'un ascenceur | AP2: ='LOT 20'!B4 -> Débroussaillage et défrichage | AR2: ='LOT 21'!B4 -> Excavation de tranchées, fouilles ou plateformes
B3: DEMOLITION | D3: ='LOT 1'!B6 -> Retrait de flocages, calorifugeages ou matériaux friables (procédure lourde avec confinement) | F3: ='LOT 2'!B5 -> Dépose des équipements techniques : luminaires, radiateurs, sanitaires | H3: ='LOT 3'!B5 -> Création de longrines, plots ou radiers | J3: ='LOT 4'!B5 -> Démontage sécurisé en toiture occupée | L3: ='LOT 5'!B5 -> Retrait des liteaux ou voliges abîmés | N3: ='LOT 6'!B5 -> Application de résines liquides (polyuréthane, epoxy) | P3: ='LOT 7'!B5 -> Démoussage / traitement fongicide | R3: ='LOT 8'!B5 -> Calfeutrement et ajustement | T3: ='LOT 9'!B8 -> POSE ITI (ossature métallique, paneaux ou rouleaux isolants, BA13) | V3: ='LOT 10'!B4 -> Pose d'une porte intérieure | X3: ='LOT 11'!B4 -> Pose d'un volet battant | Z3: ='LOT 12'!B4 -> Pose d'une porte intérieure | AB3: ='LOT 13'!B5 -> Pose d’un système d’étanchéité (SPEC, SEL) dans zones humides | AD3: ='LOT 14'!B7 -> Application d'une peinture de sol (garage, cave, locaux techniques) | AF3: ='LOT 15'!B4 -> Poser une évacuation d'EU | AH3: ='LOT 16'!B4 -> Poser une VMC | AJ3: ='LOT 17'!B4 -> Installer une pompe à chaleur | AL3: ='LOT 18'!B4 -> Installer le réseau télévision | AN3: ='LOT 19'!B6 -> Modernisation complète / remplacement d'un ascenseur | AP3: ='LOT 20'!B5 -> Abattage et dessouchage d’arbres | AR3: ='LOT 21'!B7 -> Réalisation des couches de forme
B4: GROS_ŒUVRE | D4: ='LOT 1'!B7 -> Retrait de dalles de sol ou colle amiantée | F4: ='LOT 2'!B6 -> Dépose des menuiseries (portes, fenêtres) | H4: ='LOT 3'!B6 -> Réalisation de fondations profondes (pieux, micropieux si sous-traité) | J4: ='LOT 4'!B6 -> Traitement ou renforcement ponctuel des appuis (murs, poutres) | L4: ='LOT 5'!B8 -> Mise en place de l’écran de sous-toiture (pare-pluie, pare-vapeur) | N4: ='LOT 6'!B6 -> Pose de feuilles synthétiques (PVC, EPDM) | P4: ='LOT 7'!B6 -> Application d’un fixateur ou primaire d’accrochage (si requis) | R4: ='LOT 8'!B8 -> Réalisation de cloisons (placo, BA13, etc.) sur ossature | T4: ='LOT 9'!B9 -> POSE ITI (mise en place de pare-vapeur si nécessaire) | V4: ='LOT 10'!B5 -> Pose des gardes corps et/ou mains-courantes | X4: ='LOT 11'!B5 -> Pose d'une menuiserie | Z4: ='LOT 12'!B5 -> Pose d'une porte de garage extérieure | AB4: ='LOT 13'!B8 -> Pose du carrelage au sol | AD4: ='LOT 14'!B8 -> Application d'une peinture technique (intumescente, anti-humidité, traitement moisissure) | AF4: ='LOT 15'!B5 -> Poser une baignoire | AH4: ='LOT 16'!B5 -> Poser une centrale de traitement d'air | AJ4: ='LOT 17'!B5 -> Poser un chauffe-eau | AL4: ='LOT 18'!B5 -> Installer le réseau informatique | AN4: ='LOT 19'!B8 -> Pose du tableau de commande (armoire ou armoire compacte en gaine) | AP4: ='LOT 20'!B6 -> Modelage du terrain (nivellement, création de talus, fossés, etc.) | AR4: ='LOT 21'!B8 -> Mise en place de géotextiles ou géogrilles
B5: CHARPENTE | D5: ='LOT 1'!B8 -> Aspiration ou raclage des poussières amiantées | F5: ='LOT 2'!B7 -> Dépose des revêtements : sols souples, carrelages, faïences | H5: ='LOT 3'!B9 -> Pose de blocs béton (parpaings), briques, agglos cellulaires | J5: ='LOT 4'!B9 -> Pose d'une chapente bois | L5: ='LOT 5'!B11 -> Pose des tuiles (terre cuite, béton), ardoises, bacs acier, plaques fibro-ciment (hors amiante) | N5: ='LOT 6'!B7 -> Traitement des points singuliers : relevés, angles, pénétrations | P5: ='LOT 7'!B9 -> Reprise de maçonneries (joints, éclats, fissures) | R5: ='LOT 8'!B11 -> Réalisation des faux plafonds (rails, dalles ou plaques) | T5: ='LOT 9'!B13 -> ISOLATION COMBLES PERDUS (Soufflage de laine minérale en vrac) | V5: ='LOT 10'!B6 -> Pose d'une menuiserie | X5: ='LOT 11'!B6 -> Pose d'un volet roulant à tablier PVC | Z5: ='LOT 12'!B6 -> Pose d'un store | AB5: ='LOT 13'!B9 -> Pose de plinthes carrelées ou à chant | AD5: ='LOT 14'!B13 -> REVETEMENT SOUPLE : Pose en lés ou en dalles (PVC, linoléum, caoutchouc…) | AF5: ='LOT 15'!B6 -> Poser un receveur de douche | AH5: ='LOT 16'!B6 -> Installer un split mural | AJ5: ='LOT 17'!B6 -> Poser un radiateur | AL5: ='LOT 18'!B6 -> Poser une installation électrique photovoltaïque | AN5: ='LOT 19'!B10 -> Audit des prestations d'entretien, de la sécurité et du bon fonctionnement des ascenseurs | AP5: ='LOT 20'!B9 -> Plantation (arbres, arbustes, haies) | AR5: ='LOT 21'!B9 -> Réalisation des couches de fondation (GNT, graves, etc.)
B6: COUVERTURE | D6: ='LOT 1'!B9 -> Encapsulage si conservation du support (application de fixateur ou résine) | F6: ='LOT 2'!B8 -> Dépose des réseaux intérieurs (plomberie, électricité, VMC) | H6: ='LOT 3'!B10 -> Montage de murs porteurs ou non porteurs | J6: ='LOT 4'!B12 -> Pose d'une charpente métallique (portiques, poutres, etc.) | L6: ='LOT 5'!B12 -> Pose des éléments de faîtage, rives, noues | N6: ='LOT 6'!B10 -> Pose de protections mécaniques (dalles, gravillons, plaques) | P6: ='LOT 7'!B13 -> Projection ou application manuelle | R6: ='LOT 8'!B14 -> Réalisation des réservations pour portes, fenêtres, gaines techniques | T6: ='LOT 9'!B14 -> ISOLATION COMBLES PERDUS (Pose de panneaux ou rouleaux sur le plancher) | Z6: ='LOT 12'!B7 -> Pose d'un equipement motorisé pour parking (Porte, Portail, Barrière..) | AB6: ='LOT 13'!B12 -> Pose des carreaux muraux (faïence, pâte de verre, mosaïque) | AD6: ='LOT 14'!B15 -> PARQUET : Pose flottante, collée ou clouée | AF6: ='LOT 15'!B7 -> Poser un évier | AH6: ='LOT 16'!B7 -> Remplacement d'une carte electronique de commande VMC | AJ6: ='LOT 17'!B7 -> Poser un poêle à bois ou à pellets | AL6: ='LOT 18'!B7 -> Installation d'un équipement de contrôle d'accès/ d'Interphonie | AN6: ='LOT 19'!B11 -> Contrôle technique réglementaire des ascenseurs selon les conditions imposées par le décret n° 2004-964 du 9 septembre 2004 et du décret n°2012-674 du 7 mai 2012. | AP6: ='LOT 20'!B10 -> Mise en place de gazon (semis ou pose de gazon en plaques) | AR6: ='LOT 21'!B10 -> Pose des bordures (CC1, CC2, T2, etc.)
B7: ETANCHEITE | D7: ='LOT 1'!B12 -> Aspiration de la zone avec aspirateur à filtration absolue (THE) | F7: ='LOT 2'!B12 -> Démolition de murs non porteurs à la masse, burineur | H7: ='LOT 3'!B11 -> Réalisation de chaînages horizontaux et verticaux | J7: ='LOT 4'!B13 -> Traitement anti-corrosion sur zones de coupe ou soudures | L7: ='LOT 5'!B15 -> Pose de solins d’étanchéité (zinc, plomb, PVC) | N7: ='LOT 6'!B11 -> Mise en place de protections végétales (toitures végétalisées) | P7: ='LOT 7'!B14 -> Dressage et finition (taloché, gratté, écrasé, lissé…) | R7: ='LOT 8'!B15 -> Pose des huisseries et encadrements | T7: ='LOT 9'!B17 -> ISOLATION RAMANTS DE TOITURE (Pose éventuelle d’un pare-vapeur et d’un frein vapeur) | Z7: ='LOT 12'!B8 -> Installation d'une barre de pivotement | AB7: ='LOT 13'!B13 -> Pose de profils de finition (cornières, angles sortants) | AD7: ='LOT 14'!B16 -> PARQUET : Pose de sous-couche acoustique ou thermique | AF7: ='LOT 15'!B8 -> Poser un lavabo | AL7: ='LOT 18'!B8 -> Installer un système de sécurité incendie | AP7: ='LOT 20'!B13 -> Tonte de pelouses | AR7: ='LOT 21'!B11 -> Pose de caniveaux (béton, fonte, etc.)
B8: RAVALEMENT_ENDUIT | D8: ='LOT 1'!B13 -> Lavage humide des surfaces si nécessaire | F8: ='LOT 2'!B13 -> Démolition de petits ouvrages (escaliers, murets, appuis) | H8: ='LOT 3'!B12 -> Réalisation d'ouvertures : réservations, linteaux, seuils | J8: ='LOT 4'!B16 -> Application de traitement fongicide, insecticide ou ignifuge sur bois | L8: ='LOT 5'!B16 -> Réalisation des habillages de cheminée, fenêtres de toit, chéneaux | N8: ='LOT 6'!B12 -> Réalisation de protections contre les UV ou les agressions mécaniques | P8: ='LOT 7'!B16 -> Pose d’un sous-enduit d’accrochage | T8: ='LOT 9'!B20 -> Pose de panneaux rigides sur dalle ou sous chape (polystyrène, PU, laine minérale haute densité) | Z8: ='LOT 12'!B9 -> Poser une main courante en extérieur | AD8: ='LOT 14'!B18 -> Pose de moquette | AF8: ='LOT 15'!B9 -> Poser un WC | AL8: ='LOT 18'!B10 -> Intervention sur Eclairage Extérieur (candelabre, borne,...) | AP8: ='LOT 20'!B14 -> Taille des haies et arbustes | AR8: ='LOT 21'!B12 -> Réalisation de trottoirs, cheminements piétons (béton désactivé, pavés, enrobé, etc.)
B9: DOUBLAGE_FAUX_PLAFOND_CLOISONS | F9: ='LOT 2'!B14 -> Reprise ponctuelle de dalles ou planchers | H9: ='LOT 3'!B13 -> Remplissage de murs (en rénovation) | J9: ='LOT 4'!B17 -> Peinture antirouille ou galvanisation sur éléments métalliques | L9: ='LOT 5'!B17 -> Pose de gouttières, descentes d’eau pluviale et accessoires | N9: ='LOT 6'!B15 -> Détection et réparation des infiltrations | P9: ='LOT 7'!B17 -> Application manuelle ou mécanisée de la finition (acrylique, siloxane…) | T9: ='LOT 9'!B21 -> Réalisation de chape flottante ou plancher chauffant sur isolant | AD9: ='LOT 14'!B21 -> Pose de plinthes assorties ou de finition | AF9: ='LOT 15'!B10 -> Poser les conduites gaz | AL9: Travaux sur réseau électrique / Mise en sécurité électrique | AP9: ='LOT 20'!B15 -> Ramassage de feuilles | AR9: ='LOT 21'!B13 -> Réalisation de chaussées : enrobé, béton, pavés, bicouche, etc.
B10: ISOLATION | F10: ='LOT 2'!B16 -> Démolition de murs porteurs au BRH (brise-roche hydraulique) | H10: ='LOT 3'!B16 -> Coffrage traditionnel ou modulaire (panneaux métalliques, bois) | J10: ='LOT 4'!B18 -> Pose de pare-vapeur ou pare-pluie en sous-toiture si nécessaire | L10: ='LOT 5'!B18 -> Mise en place des protections contre la neige ou le vent (stop-neige, grillages) | N10: ='LOT 6'!B16 -> Réfection partielle de membranes ou joints | P10: ='LOT 7'!B20 -> Application d’un fixateur ou impression | T10: ='LOT 9'!B24 -> Traitement des ponts thermiques en nez de dalle ou refends | AD10: ='LOT 14'!B22 -> Barres de seuil et accessoires | AF10: ='LOT 15'!B11 -> Poser/Remplacer une canalisation EP | AP10: ='LOT 20'!B16 -> Nettoyage et curage des fossés, bassins ou caniveaux | AR10: ='LOT 21'!B16 -> Réseaux d’assainissement eaux usées (EU)
B11: MENUISERIES_INTERIEURES | F11: ='LOT 2'!B17 -> Démolition de planchers béton ou structures métalliques | H11: ='LOT 3'!B17 -> Coulage des voiles et poteaux béton (avec contrôle vibrage et cure) | J11: ='LOT 4'!B21 -> Remplacement d’éléments de charpente affaiblis | L11: ='LOT 5'!B21 -> Réparation de tuiles cassées ou déplacées | N11: ='LOT 6'!B17 -> Nettoyage des chéneaux, évacuations d’eau pluviale | P11: ='LOT 7'!B21 -> Mise en œuvre de deux couches de peinture de façade (acrylique, siloxane, minérale…) | AD11: ='LOT 14'!B23 -> Joints de dilatation ou de fractionnement | AF11: Mettre en apparent les réseaux | AP11: ='LOT 20'!B19 -> Pose de mobilier urbain (bancs, corbeilles, barrières) | AR11: ='LOT 21'!B17 -> Réseaux d’eaux pluviales (EP)
B12: MENUISERIES_EXTERIEURES | F12: ='LOT 2'!B18 -> Abattage de bâtiment (grignotage ou abattage à la pelle) | H12: ='LOT 3'!B18 -> Pose de prédalles, poutrelles, hourdis | J12: ='LOT 4'!B22 -> Pose de pièces de renfort (potelet, sabot, doublage) | L12: ='LOT 5'!B22 -> Remplacement de liteaux ou éléments bois pourris | P12: ='LOT 7'!B22 -> Pose / Dépose bardage bois en facade | AF12: ='LOT 15'!B12 -> 0 | AP12: ='LOT 20'!B20 -> Création d’allées piétonnes (graviers, pavés, enrobé) | AR12: ='LOT 21'!B18 -> Pose de canalisations (PVC, béton, fonte, etc.)
B13: SERRURERIE | F13: ='LOT 2'!B19 -> Sciage et carottage de béton (création de trémies ou réservations) | H13: ='LOT 3'!B19 -> Coulage de dalles pleine, sur coffrage, ou sur entrevous | J13: ='LOT 4'!B23 -> Traitement curatif de bois attaqué (champignons, insectes) | L13: ='LOT 5'!B23 -> Colmatage de fuites ou infiltrations | P13: ='LOT 7'!B23 -> Pose / Dépose panneau d'habillage en facade | AP13: ='LOT 20'!B21 -> Installation de clôtures végétales ou rigides | AR13: ='LOT 21'!B19 -> Pose de regards, avaloirs, grilles
B14: CARRELAGE_FAIENCE | F14: ='LOT 2'!B22 -> Démolition de cheminées ou souches en toiture | H14: ='LOT 3'!B20 -> Réalisation de trémies, gaines, cages d’escalier | L14: ='LOT 5'!B24 -> Nettoyage de la toiture (débris, mousses, feuilles) | AP14: ='LOT 20'!B22 -> Création de murets paysagers, escaliers ou éléments décoratifs | AR14: ='LOT 21'!B20 -> Étanchéité et essais de réseaux
B15: PEINTURE_REVETEMENTS_DE_SOL | F15: ='LOT 2'!B23 -> Dépose de fondations superficielles | H15: ='LOT 3'!B23 -> Ouverture de murs porteurs (avec pose de linteaux ou poutres métalliques) | AP15: ='LOT 20'!B23 -> Mise en place de bordures, pas japonais, pergolas | AR15: ='LOT 21'!B23 -> Réseaux d’électricité (basse tension, éclairage public)
B16: PLOMBERIE | F16: ='LOT 2'!B24 -> Sciage de dalles ou murs en milieux contraints | H16: ='LOT 3'!B24 -> Renforcement de planchers (résines, fibres, béton armé complémentaire) | AP16: Abri de jardin | AR16: ='LOT 21'!B24 -> Réseaux de télécommunications (fourreaux, chambres de tirage)
B17: VENTILATION | F17: ='LOT 2'!B25 -> Intervention en site occupé (zones horaires, protections renforcées) | H17: ='LOT 3'!B25 -> Réalisation de massifs ou socles pour équipements techniques | AR17: ='LOT 21'!B25 -> Réseaux de gaz (avec entreprise agréée)
B18: CHAUFFAGE | F18: ='LOT 2'!B26 -> Travaux en milieu urbain / bâtiment mitoyen (procédures spécifiques) | H18: ='LOT 3'!B26 -> Injecteurs / coulis pour consolidation si zone sensible | AR18: ='LOT 21'!B26 -> Réseaux de fibre optique (fourreaux, boîtiers)
B19: ELECTRICITE | H19: ='LOT 3'!B29 -> Réservations pour réseaux techniques (gaines, traversées) | AR19: ='LOT 21'!B27 -> Pose de gaines, chambres, coffrets
B20: ASCENCEURS | H20: ='LOT 3'!B32 -> Pose de membranes d’étanchéité sous dallage | AR20: ='LOT 21'!B30 -> Pose de candélabres, bornes lumineuses
B21: ESPACES_VERTS | H21: ='LOT 3'!B33 -> Traitement des joints de dilatation ou de construction | AR21: ='LOT 21'!B31 -> Installation d’armoires de commande
B22: VOIRIES_RESEAUX_DIVERS | H22: ='LOT 3'!B34 -> Application de produit de cure, hydrofuge, ou traitement anti-carbonatation | AR22: ='LOT 21'!B34 -> Création de noues paysagères
B23: TOUT_CORPS_ETAT | H23: Audit structurel et sécuritaire des balcons et garde-corps | AR23: ='LOT 21'!B35 -> Fossés drainants
AR24: ='LOT 21'!B36 -> Tranchées d’infiltration
AR25: ='LOT 21'!B37 -> Bassins de rétention ou d’infiltration
AR26: ='LOT 21'!B38 -> Pose de séparateurs hydrocarbures
AR27: ='LOT 21'!B40 -> 0
AR28: ='LOT 21'!B41 -> 0
AR29: ='LOT 21'!B42 -> 0
A33: CHARGE_OPERATION
A34: PRENOM | B34: NOM | C34: TELEPHONE | E34: MAIL
A35: DOMINIQUE BOGNI | C35: 06 89 87 86 91 | E35: dominique.bogni@plurial.fr
A36: CHRISTOPHE CARON | C36: 06 82 93 66 29 | E36: christophe.caron@plurial.fr
A37: LAURENCE CHARBONNIER | C37: 06 13 55 18 75 | E37: laurence.charbonnier@plurial.fr
A38: SEBASTIEN HERAULT | C38: 06 09 54 49 48 | E38: sebastien.herault@plurial.fr
A39: JEROME BELLIEN | C39: 07 85 09 60 87 | E39: jerome.bellien@plurial.fr
A40: SAMY WAHHAM | C40: 06 07 33 79 00 | E40: samy.wahham@plurial.fr
A41: FABRICE DAUMAL | C41: 06 28 11 35 94 | E41: fabrice.daumal@plurial.fr
A42: MAXIME OYANCE | C42: 06 11 07 15 29 | E42: maxime.oyance@plurial.fr
A43: CAMILLE DUVAL LELONG | C43: 06 27 34 18 33 | E43: camille.lelong@plurial.fr
...

Sheet LISTE LOTS
A1: N° | B1: NOM
A2: 1 | B2: DESAMIANTAGE
A3: =A2+1 -> 2 | B3: DEMOLITION
A4: =A3+1 -> 3 | B4: GROS ŒUVRE
A5: =A4+1 -> 4 | B5: CHARPENTE
A6: =A5+1 -> 5 | B6: COUVERTURE
A7: =A6+1 -> 6 | B7: ETANCHEITE
A8: =A7+1 -> 7 | B8: RAVALEMENT DE FACADE / ENDUIT
A9: =A8+1 -> 8 | B9: DOUBLAGE / FAUX PLAFOND / CLOISONS
A10: =A9+1 -> 9 | B10: ISOLATION
A11: =A10+1 -> 10 | B11: MENUISERIES INTERIEURES
A12: =A11+1 -> 11 | B12: MENUISERIES EXTERIEURES
A13: =A12+1 -> 12 | B13: SERRURERIE
A14: =A13+1 -> 13 | B14: CARRELAGE ET FAIENCE
... A22: =A21+1 -> 21 | B22: VOIRIES ET RESEAUX DIVERS

Sheet LOT 1
A1: N°1 DESAMIANTAGE
A2: N° | B2: NOM TACHE
A3: 1. Retrait ou traitement de l’amiante
A4: (selon nature du matériau et procédure SS3 ou SS4)
A5: 1.1 | B5: Dépose de plaques ou éléments en amiante-ciment (toiture, conduits, bardage)
A6: 1.2 | B6: Retrait de flocages, calorifugeages ou matériaux friables (procédure lourde avec confinement)
A7: 1.3 | B7: Retrait de dalles de sol ou colle amiantée
A8: 1.4 | B8: Aspiration ou raclage des poussières amiantées
A9: 1.5 | B9: Encapsulage si conservation du support (application de fixateur ou résine)
A11: 2. Nettoyage et décontamination
A12: 2.1 | B12: Aspiration de la zone avec aspirateur à filtration absolue (THE)
A13: 2.2 | B13: Lavage humide des surfaces si nécessaire

Sheet LOT 2
A1: N°2 DEMOLITION
A2: N° | B2: NOM TACHE
A3: 1. Curage préalable
A4: 1.1 | B4: Dépose des éléments non porteurs : cloisons, plafonds, doublages
A5: 1.2 | B5: Dépose des équipements techniques : luminaires, radiateurs, sanitaires
A6: 1.3 | B6: Dépose des menuiseries (portes, fenêtres)
A7: 1.4 | B7: Dépose des revêtements : sols souples, carrelages, faïences
A8: 1.5 | B8: Dépose des réseaux intérieurs (plomberie, électricité, VMC)
A10: 2. Démolition des éléments bâtis
A11: Démolition manuelle
A12: 2.1 | B12: Démolition de murs non porteurs à la masse, burineur
A13: 2.2 | B13: Démolition de petits ouvrages (escaliers, murets, appuis)
A14: 2.3 | B14: Reprise ponctuelle de dalles ou planchers
A15: Démolition mécanique
A16: 2.4 | B16: Démolition de murs porteurs au BRH (brise-roche hydraulique)
A17: 2.5 | B17: Démolition de planchers béton ou structures métalliques
A18: 2.6 | B18: Abattage de bâtiment (grignotage ou abattage à la pelle)
A19: 2.7 | B19: Sciage et carottage de béton (création de trémies ou réservations)
A21: 3. Cas particuliers
A22: 3.1 | B22: Démolition de cheminées ou souches en toiture
A23: 3.2 | B23: Dépose de fondations superficielles
A24: 3.3 | B24: Sciage de dalles ou murs en milieux contraints
A25: 3.4 | B25: Intervention en site occupé (zones horaires, protections renforcées)
A26: 3.5 | B26: Travaux en milieu urbain / bâtiment mitoyen (procédures spécifiques)

Sheet LOT 3
A1: N°3 GROS ŒUVRE
A2: N° | B2: NOM TACHE
A3: 1. Fondations
A4: 1.1 | B4: Réalisation de semelles filantes ou isolées en béton armé
A5: 1.2 | B5: Création de longrines, plots ou radiers
A6: 1.3 | B6: Réalisation de fondations profondes (pieux, micropieux si sous-traité)
A8: 2. Élévations en maçonnerie
A9: 2.1 | B9: Pose de blocs béton (parpaings), briques, agglos cellulaires
A10: 2.2 | B10: Montage de murs porteurs ou non porteurs
A11: 2.3 | B11: Réalisation de chaînages horizontaux et verticaux
A12: 2.4 | B12: Réalisation d'ouvertures : réservations, linteaux, seuils
A13: 2.5 | B13: Remplissage de murs (en rénovation)
A15: 3. Béton armé (banché ou préfabriqué)
A16: 3.1 | B16: Coffrage traditionnel ou modulaire (panneaux métalliques, bois)
A17: 3.2 | B17: Coulage des voiles et poteaux béton (avec contrôle vibrage et cure)
A18: 3.3 | B18: Pose de prédalles, poutrelles, hourdis
A19: 3.4 | B19: Coulage de dalles pleine, sur coffrage, ou sur entrevous
A20: 3.5 | B20: Réalisation de trémies, gaines, cages d’escalier
A22: 4. Reprises en sous-œuvre / renforcement
A23: 4.1 | B23: Ouverture de murs porteurs (avec pose de linteaux ou poutres métalliques)
A24: 4.2 | B24: Renforcement de planchers (résines, fibres, béton armé complémentaire)
A25: 4.3 | B25: Réalisation de massifs ou socles pour équipements techniques
A26: 4.4 | B26: Injecteurs / coulis pour consolidation si zone sensible
A28: 5. Réservation, intégration, coordination
A29: 5.1 | B29: Réservations pour réseaux techniques (gaines, traversées)
A31: 6. Étanchéité et traitement des bétons
A32: 6.1 | B32: Pose de membranes d’étanchéité sous dallage
A33: 6.2 | B33: Traitement des joints de dilatation ou de construction
A34: 6.3 | B34: Application de produit de cure, hydrofuge, ou traitement anti-carbonatation

Sheet LOT 4
A1: N°4 CHARPENTE
A2: N° | B2: NOM TACHE
A3: 1. Dépose (en cas de rénovation)
A4: 1.1 | B4: Dépose de l’ancienne charpente ou de parties défectueuses
A5: 1.2 | B5: Démontage sécurisé en toiture occupée
A6: 1.4 | B6: Traitement ou renforcement ponctuel des appuis (murs, poutres)
A8: 2. Pose de charpente bois
A9: 2.1 | B9: Pose d'une chapente bois
A11: 3. Pose de charpente métallique
A12: 3.1 | B12: Pose d'une charpente métallique (portiques, poutres, etc.)
A13: 3.2 | B13: Traitement anti-corrosion sur zones de coupe ou soudures
A15: 4. Traitement et protection
A16: 4.1 | B16: Application de traitement fongicide, insecticide ou ignifuge sur bois
A17: 4.2 | B17: Peinture antirouille ou galvanisation sur éléments métalliques
A18: 4.3 | B18: Pose de pare-vapeur ou pare-pluie en sous-toiture si nécessaire
A20: 5. Maintenance (le cas échéant)
A21: 5.1 | B21: Remplacement d’éléments de charpente affaiblis
A22: 5.2 | B22: Pose de pièces de renfort (potelet, sabot, doublage)
A23: 5.3 | B23: Traitement curatif de bois attaqué (champignons, insectes)

Sheet LOT 5
A1: N°5 COUVERTURE
A2: N° | B2: NOM TACHE
A3: 1. Dépose de la couverture existante
A4: 1.1 | B4: Dépose des éléments de couverture (tuiles, ardoises, bac acier)
A5: 1.2 | B5: Retrait des liteaux ou voliges abîmés
A7: 2. Pose de l’écran sous-toiture
A8: 2.1 | B8: Mise en place de l’écran de sous-toiture (pare-pluie, pare-vapeur)
A10: 3. Pose des matériaux de couverture
A11: 3.1 | B11: Pose des tuiles (terre cuite, béton), ardoises, bacs acier, plaques fibro-ciment (hors amiante)
A12: 3.2 | B12: Pose des éléments de faîtage, rives, noues
A14: 4. Étanchéité et accessoires
A15: 4.1 | B15: Pose de solins d’étanchéité (zinc, plomb, PVC)
A16: 4.2 | B16: Réalisation des habillages de cheminée, fenêtres de toit, chéneaux
A17: 4.3 | B17: Pose de gouttières, descentes d’eau pluviale et accessoires
A18: 4.4 | B18: Mise en place des protections contre la neige ou le vent (stop-neige, grillages)
A20: 6. Réparations et maintenance
A21: 6.1 | B21: Réparation de tuiles cassées ou déplacées
A22: 6.2 | B22: Remplacement de liteaux ou éléments bois pourris
A23: 6.3 | B23: Colmatage de fuites ou infiltrations
A24: 6.4 | B24: Nettoyage de la toiture (débris, mousses, feuilles)

Sheet LOT 6
A1: N°6 ETANCHEITE
A2: N° | B2: NOM TACHE
A3: 1. Mise en œuvre de l’étanchéité
A4: 1.1 | B4: Pose de membranes bitumineuses (torchis, rouleaux)
A5: 1.2 | B5: Application de résines liquides (polyuréthane, epoxy)
A6: 1.3 | B6: Pose de feuilles synthétiques (PVC, EPDM)
A7: 1.4 | B7: Traitement des points singuliers : relevés, angles, pénétrations
A9: 2. Protection de l’étanchéité
A10: 2.1 | B10: Pose de protections mécaniques (dalles, gravillons, plaques)
A11: 2.2 | B11: Mise en place de protections végétales (toitures végétalisées)
A12: 2.3 | B12: Réalisation de protections contre les UV ou les agressions mécaniques
A14: 3. Réparations et entretien
A15: 3.1 | B15: Détection et réparation des infiltrations
A16: 3.2 | B16: Réfection partielle de membranes ou joints
A17: 3.3 | B17: Nettoyage des chéneaux, évacuations d’eau pluviale

Sheet LOT 7
A1: N°7 RAVALEMENT DE FACADE / ENDUIT
A2: N° | B2: NOM TACHE
A3: 1. Préparation des supports
A4: 1.1 | B4: Nettoyage des façades (haute pression, sablage, gommage, peeling selon nature du support)
A5: 1.2 | B5: Démoussage / traitement fongicide
A6: 1.3 | B6: Application d’un fixateur ou primaire d’accrochage (si requis)
A8: 2. Réparations ponctuelles
A9: 2.1 | B9: Reprise de maçonneries (joints, éclats, fissures)
A11: 3. Application d’enduits
A12: Enduit monocouche ou multicouche (à la chaux, ciment, RPE…)
A13: 3.1 | B13: Projection ou application manuelle
A14: 3.2 | B14: Dressage et finition (taloché, gratté, écrasé, lissé…)
A15: Enduit décoratif ou finition RSE / RPE
A16: 3.3 | B16: Pose d’un sous-enduit d’accrochage
A17: 3.4 | B17: Application manuelle ou mécanisée de la finition (acrylique, siloxane…)
A19: 4. Ravalement avec peinture (si applicable)
A20: 4.1 | B20: Application d’un fixateur ou impression
A21: 4.2 | B21: Mise en œuvre de deux couches de peinture de façade (acrylique, siloxane, minérale…)
A22: 4.2 | B22: Pose / Dépose bardage bois en facade
A23: 4.2 | B23: Pose / Dépose panneau d'habillage en facade

Sheet LOT 8
A1: N°8 DOUBLAGE / FAUX PLAFOND / CLOISONS
A2: N° | B2: NOM TACHE
A3: 1. Pose des isolants
A4: 1.1 | B4: Mise en place de l’isolation thermique, acoustique ou pare-vapeur dans les doublages ou cloisons
A5: 1.2 | B5: Calfeutrement et ajustement
A7: 2. Réalisation de cloisons
A8: 2.1 | B8: Réalisation de cloisons (placo, BA13, etc.) sur ossature
A10: 3. Réalisation des faux plafonds
A11: 3.1 | B11: Réalisation des faux plafonds (rails, dalles ou plaques)
A13: 4. Ouvertures et accessoires
A14: 4.1 | B14: Réalisation des réservations pour portes, fenêtres, gaines techniques
A15: 4.2 | B15: Pose des huisseries et encadrements

Sheet LOT 9
A1: N°9 ISOLATION
A2: N° | B2: NOM TACHE
A3: 1. Isolation des murs (extérieure)
A4: 1.2 | B4: POSE ITE : Pose d'isolant par collage ou fixation mécanique (chevilles à rosace)
A6: 2. Isolation des murs (intérieure)
A7: Pose en doublage sur ossature :
A8: 2.1 | B8: POSE ITI (ossature métallique, paneaux ou rouleaux isolants, BA13)
A9: 2.3 | B9: POSE ITI (mise en place de pare-vapeur si nécessaire)
A11: 3. Isolation des combles et toitures
A12: Combles perdus :
A13: 3.1 | B13: ISOLATION COMBLES PERDUS (Soufflage de laine minérale en vrac)
A14: 3.2 | B14: ISOLATION COMBLES PERDUS (Pose de panneaux ou rouleaux sur le plancher)
A15: Rampants de toiture (sous toiture) :
A16: 3.3 | B16: ISOLATION RAMANTS DE TOITURE (Pose entre chevrons ou en double couche croisée)
A17: 3.4 | B17: ISOLATION RAMANTS DE TOITURE (Pose éventuelle d’un pare-vapeur et d’un frein vapeur)
A19: 4. Isolation des planchers et dalles
A20: 4.1 | B20: Pose de panneaux rigides sur dalle ou sous chape (polystyrène, PU, laine minérale haute densité)
A21: 4.2 | B21: Réalisation de chape flottante ou plancher chauffant sur isolant
A23: 5. Isolation des plafonds / sous-faces
A24: 5.1 | B24: Traitement des ponts thermiques en nez de dalle ou refends

Sheet LOT 10
A1: N°10 MENUISERIES INTERIEURES
A2: N° | B2: NOM TACHE
A3: 1 | B3: Pose des habillages divers (plinthes compris)
A4: 2 | B4: Pose d'une porte intérieure
A5: 3 | B5: Pose des gardes corps et/ou mains-courantes
A6: 4 | B6: Pose d'une menuiserie

Sheet LOT 11
A1: N°11 MENUISERIES EXTERIEURES
A2: N° | B2: NOM TACHE
A3: 1 | B3: Pose d'une portée d'entrée de bâtiment
A4: 2 | B4: Pose d'un volet battant
A5: 3 | B5: Pose d'une menuiserie
A6: 4 | B6: Pose d'un volet roulant à tablier PVC

Sheet LOT 12
A1: N°12 SERRURERIE
A2: N° | B2: NOM TACHE
A3: 1 | B3: Pose d'une portée d'entrée de bâtiment
A4: 2 | B4: Pose d'une porte intérieure
A5: 3 | B5: Pose d'une porte de garage extérieure
A6: 4 | B6: Pose d'un store
A7: 5 | B7: Pose d'un equipement motorisé pour parking (Porte, Portail, Barrière..)
A8: 6 | B8: Installation d'une barre de pivotement
A9: 7 | B9: Poser une main courante en extérieur

Sheet LOT 13
A1: N°13 CARRELAGE FAIENCE
A2: N° | B2: NOM TACHE
A3: 1. Préparation du support
A4: 1.1 | B4: Application d’un primaire d’accrochage si nécessaire
A5: 1.2 | B5: Pose d’un système d’étanchéité (SPEC, SEL) dans zones humides
A7: 2. Pose du carrelage au sol
A8: 2.1 | B8: Pose du carrelage au sol
A9: 2.2 | B9: Pose de plinthes carrelées ou à chant
A11: 3. Pose de faïence murale
A12: 3.1 | B12: Pose des carreaux muraux (faïence, pâte de verre, mosaïque)
A13: 3.2 | B13: Pose de profils de finition (cornières, angles sortants)

Sheet LOT 14
A1: N°14 PEINTURE / REVETEMENTS DE SOL
A2: N° | B2: PEINTURE
A3: 2. Application des couches de peinture
A4: 2.1 | B4: Application des couches de peinture (primaire, finition)
A6: 3. Travaux spécifiques
A7: 3.1 | B7: Application d'une peinture de sol (garage, cave, locaux techniques)
A8: 3.2 | B8: Application d'une peinture technique (intumescente, anti-humidité, traitement moisissure)
A10: N° | B10: REVETEMENT DE SOL
A11: 2. Pose du revêtement
A12: Revêtements souples :
A13: 2.1 | B13: REVETEMENT SOUPLE : Pose en lés ou en dalles (PVC, linoléum, caoutchouc…)
A14: Parquet (massif, contrecollé, stratifié) :
A15: 2.4 | B15: PARQUET : Pose flottante, collée ou clouée
A16: 2.5 | B16: PARQUET : Pose de sous-couche acoustique ou thermique
A17: Moquette :
A18: 2.7 | B18: Pose de moquette
A20: 3. Finitions
A21: 3.1 | B21: Pose de plinthes assorties ou de finition
A22: 3.2 | B22: Barres de seuil et accessoires
A23: 3.3 | B23: Joints de dilatation ou de fractionnement

Sheet LOT 15
A1: N°15 PLOMBERIE
A2: N° | B2: NOM TACHE
A3: 1 | B3: Poser un réseau multicouche
A4: 2 | B4: Poser une évacuation d'EU
A5: 3 | B5: Poser une baignoire
A6: 4 | B6: Poser un receveur de douche
A7: 5 | B7: Poser un évier
A8: 6 | B8: Poser un lavabo
A9: 7 | B9: Poser un WC
A10: 8 | B10: Poser les conduites gaz
A11: 9 | B11: Poser/Remplacer une canalisation EP

Sheet LOT 16
A1: N°16 VENTILATION
A2: N° | B2: NOM TACHE
A3: 1 | B3: Poser des gaines de ventilation
A4: 2 | B4: Poser une VMC
A5: 3 | B5: Poser une centrale de traitement d'air
A6: 4 | B6: Installer un split mural
A7: 5 | B7: Remplacement d'une carte electronique de commande VMC
A8: 6
A9: 7

Sheet LOT 17
A1: N°17 CHAUFFAGE
A2: N° | B2: NOM TACHE
A3: 1 | B3: Poser une chaudière gaz
A4: 2 | B4: Installer une pompe à chaleur
A5: 3 | B5: Poser un chauffe-eau
A6: 4 | B6: Poser un radiateur
A7: 5 | B7: Poser un poêle à bois ou à pellets

Sheet LOT 18
A1: N°14 ELECTRICITE
A2: N° | B2: NOM TACHE
A3: 1 | B3: Installer le réseau téléphonique
A4: 2 | B4: Installer le réseau télévision
A5: 3 | B5: Installer le réseau informatique
A6: 4 | B6: Poser une installation électrique photovoltaïque
A7: 5 | B7: Installation d'un équipement de contrôle d'accès/ d'Interphonie
A8: 6 | B8: Installer un système de sécurité incendie
A9: 7 | B9: Poser le réseau électique d'un logement
A10: 8 | B10: Intervention sur Eclairage Extérieur (candelabre, borne,...)

Sheet LOT 19
A1: N°19 ASCENCEURS
A2: N° | B2: NOM TACHE
A3: 1. Installation de l’ascenseur
A4: Partie mécanique
A5: 1.1 | B5: Installation d'un ascenceur
A6: 1.2 | B6: Modernisation complète / remplacement d'un ascenseur
A7: Partie électrique / commande
A8: 1.3 | B8: Pose du tableau de commande (armoire ou armoire compacte en gaine)
A9: 2. Audit et contrôle
A10: 2.1 | B10: Audit des prestations d'entretien, de la sécurité et du bon fonctionnement des ascenseurs
A11: 2.2 | B11: Contrôle technique réglementaire des ascenseurs selon les conditions imposées par le décret n° 2004-964 du 9 septembre 2004 et du décret n°2012-674 du 7 mai 2012.

Sheet LOT 20
A1: N°20 ESPACES VERTS
A2: N° | B2: NOM TACHE
A3: 1. Terrassement et préparation des sols
A4: 1.1 | B4: Débroussaillage et défrichage
A5: 1.2 | B5: Abattage et dessouchage d’arbres
A6: 1.3 | B6: Modelage du terrain (nivellement, création de talus, fossés, etc.)
A8: 2. Plantation
A9: 2.1 | B9: Plantation (arbres, arbustes, haies)
A10: 2.2 | B10: Mise en place de gazon (semis ou pose de gazon en plaques)
A12: 4. Entretien courant (si marché de maintenance)
A13: 4.1 | B13: Tonte de pelouses
A14: 4.2 | B14: Taille des haies et arbustes
A15: 4.3 | B15: Ramassage de feuilles
A16: 4.4 | B16: Nettoyage et curage des fossés, bassins ou caniveaux
A18: 5. Aménagements paysagers
A19: 5.1 | B19: Pose de mobilier urbain (bancs, corbeilles, barrières)
A20: 5.2 | B20: Création d’allées piétonnes (graviers, pavés, enrobé)
A21: 5.3 | B21: Installation de clôtures végétales ou rigides
A22: 5.4 | B22: Création de murets paysagers, escaliers ou éléments décoratifs
A23: 5.5 | B23: Mise en place de bordures, pas japonais, pergolas

Sheet LOT 21
A1: N°21 VOIRIES ET DIVERS
A2: N° | B2: NOM TACHE
A3: 1. Terrassements généraux
A4: 1.1 | B4: Excavation de tranchées, fouilles ou plateformes
A6: 2. Voirie (chaussées, trottoirs, cheminements)
A7: 2.1 | B7: Réalisation des couches de forme
A8: 2.2 | B8: Mise en place de géotextiles ou géogrilles
A9: 2.3 | B9: Réalisation des couches de fondation (GNT, graves, etc.)
A10: 2.4 | B10: Pose des bordures (CC1, CC2, T2, etc.)
A11: 2.5 | B11: Pose de caniveaux (béton, fonte, etc.)
A12: 2.6 | B12: Réalisation de trottoirs, cheminements piétons (béton désactivé, pavés, enrobé, etc.)
A13: 2.7 | B13: Réalisation de chaussées : enrobé, béton, pavés, bicouche, etc.
A15: 3. Réseaux humides
A16: 3.1 | B16: Réseaux d’assainissement eaux usées (EU)
A17: 3.2 | B17: Réseaux d’eaux pluviales (EP)
A18: 3.3 | B18: Pose de canalisations (PVC, béton, fonte, etc.)
A19: 3.4 | B19: Pose de regards, avaloirs, grilles
A20: 3.5 | B20: Étanchéité et essais de réseaux
A22: 4. Réseaux secs
A23: 4.1 | B23: Réseaux d’électricité (basse tension, éclairage public)
A24: 4.2 | B24: Réseaux de télécommunications (fourreaux, chambres de tirage)
A25: 4.3 | B25: Réseaux de gaz (avec entreprise agréée)
A26: 4.4 | B26: Réseaux de fibre optique (fourreaux, boîtiers)
A27: 4.5 | B27: Pose de gaines, chambres, coffrets
A29: 5. Éclairage public et mobilier urbain
A30: 5.1 | B30: Pose de candélabres, bornes lumineuses
A31: 5.2 | B31: Installation d’armoires de commande
A33: 6. Gestion des eaux pluviales et infiltration
A34: 6.1 | B34: Création de noues paysagères
A35: 6.2 | B35: Fossés drainants
A36: 6.3 | B36: Tranchées d’infiltration
A37: 6.4 | B37: Bassins de rétention ou d’infiltration
A38: 6.5 | B38: Pose de séparateurs hydrocarbures
B39: Refection voirie et abords
